2023-12-08 19:33:54,130 : ERROR : app : log_exception : 1414 : (Process Details : (104235, MainProcess), Thread Details : (139986481899072, Thread-2)) Log : Exception on /api/states/1/party/2/platform/feed [GET]\nTraceback (most recent call last):\n  File "/home/ai/project/varunClone/venv/lib/python3.9/site-packages/flask/app.py", line 2190, in wsgi_app\n    response = self.full_dispatch_request()\n  File "/home/ai/project/varunClone/venv/lib/python3.9/site-packages/flask/app.py", line 1487, in full_dispatch_request\n    return self.finalize_request(rv)\n  File "/home/ai/project/varunClone/venv/lib/python3.9/site-packages/flask/app.py", line 1506, in finalize_request\n    response = self.make_response(rv)\n  File "/home/ai/project/varunClone/venv/lib/python3.9/site-packages/flask/app.py", line 1801, in make_response\n    raise TypeError(\nTypeError: The view function for 'states_app.stateList' did not return a valid response. The function either returned None or ended without a return statement.
2023-12-08 19:35:10,789 : ERROR : app : log_exception : 1414 : (Process Details : (104235, MainProcess), Thread Details : (139986481899072, Thread-3)) Log : Exception on /api/states/1/party/2/platform/feed [GET]\nTraceback (most recent call last):\n  File "/home/ai/project/varunClone/venv/lib/python3.9/site-packages/flask/app.py", line 2190, in wsgi_app\n    response = self.full_dispatch_request()\n  File "/home/ai/project/varunClone/venv/lib/python3.9/site-packages/flask/app.py", line 1487, in full_dispatch_request\n    return self.finalize_request(rv)\n  File "/home/ai/project/varunClone/venv/lib/python3.9/site-packages/flask/app.py", line 1506, in finalize_request\n    response = self.make_response(rv)\n  File "/home/ai/project/varunClone/venv/lib/python3.9/site-packages/flask/app.py", line 1801, in make_response\n    raise TypeError(\nTypeError: The view function for 'states_app.stateList' did not return a valid response. The function either returned None or ended without a return statement.
2023-12-08 19:37:56,726 : ERROR : app : log_exception : 1414 : (Process Details : (106161, MainProcess), Thread Details : (140169807357504, Thread-3)) Log : Exception on /api/states/platform/feed [GET]\nTraceback (most recent call last):\n  File "/home/ai/project/varunClone/venv/lib/python3.9/site-packages/flask/app.py", line 2190, in wsgi_app\n    response = self.full_dispatch_request()\n  File "/home/ai/project/varunClone/venv/lib/python3.9/site-packages/flask/app.py", line 1487, in full_dispatch_request\n    return self.finalize_request(rv)\n  File "/home/ai/project/varunClone/venv/lib/python3.9/site-packages/flask/app.py", line 1506, in finalize_request\n    response = self.make_response(rv)\n  File "/home/ai/project/varunClone/venv/lib/python3.9/site-packages/flask/app.py", line 1801, in make_response\n    raise TypeError(\nTypeError: The view function for 'states_app.stateList' did not return a valid response. The function either returned None or ended without a return statement.
2023-12-08 19:38:01,623 : ERROR : app : log_exception : 1414 : (Process Details : (106161, MainProcess), Thread Details : (140169807357504, Thread-4)) Log : Exception on /api/states/platform/feed [GET]\nTraceback (most recent call last):\n  File "/home/ai/project/varunClone/venv/lib/python3.9/site-packages/flask/app.py", line 2190, in wsgi_app\n    response = self.full_dispatch_request()\n  File "/home/ai/project/varunClone/venv/lib/python3.9/site-packages/flask/app.py", line 1487, in full_dispatch_request\n    return self.finalize_request(rv)\n  File "/home/ai/project/varunClone/venv/lib/python3.9/site-packages/flask/app.py", line 1506, in finalize_request\n    response = self.make_response(rv)\n  File "/home/ai/project/varunClone/venv/lib/python3.9/site-packages/flask/app.py", line 1801, in make_response\n    raise TypeError(\nTypeError: The view function for 'states_app.stateList' did not return a valid response. The function either returned None or ended without a return statement.
2023-12-08 19:39:30,479 : ERROR : app : log_exception : 1414 : (Process Details : (106350, MainProcess), Thread Details : (140534226617920, Thread-2)) Log : Exception on /api/states/platform [GET]\nTraceback (most recent call last):\n  File "/home/ai/project/varunClone/venv/lib/python3.9/site-packages/flask/app.py", line 2190, in wsgi_app\n    response = self.full_dispatch_request()\n  File "/home/ai/project/varunClone/venv/lib/python3.9/site-packages/flask/app.py", line 1487, in full_dispatch_request\n    return self.finalize_request(rv)\n  File "/home/ai/project/varunClone/venv/lib/python3.9/site-packages/flask/app.py", line 1506, in finalize_request\n    response = self.make_response(rv)\n  File "/home/ai/project/varunClone/venv/lib/python3.9/site-packages/flask/app.py", line 1801, in make_response\n    raise TypeError(\nTypeError: The view function for 'states_app.stateList' did not return a valid response. The function either returned None or ended without a return statement.
2023-12-08 19:39:33,245 : ERROR : app : log_exception : 1414 : (Process Details : (106350, MainProcess), Thread Details : (140534226617920, Thread-3)) Log : Exception on /api/states/platform [GET]\nTraceback (most recent call last):\n  File "/home/ai/project/varunClone/venv/lib/python3.9/site-packages/flask/app.py", line 2190, in wsgi_app\n    response = self.full_dispatch_request()\n  File "/home/ai/project/varunClone/venv/lib/python3.9/site-packages/flask/app.py", line 1487, in full_dispatch_request\n    return self.finalize_request(rv)\n  File "/home/ai/project/varunClone/venv/lib/python3.9/site-packages/flask/app.py", line 1506, in finalize_request\n    response = self.make_response(rv)\n  File "/home/ai/project/varunClone/venv/lib/python3.9/site-packages/flask/app.py", line 1801, in make_response\n    raise TypeError(\nTypeError: The view function for 'states_app.stateList' did not return a valid response. The function either returned None or ended without a return statement.
2023-12-08 19:44:19,551 : ERROR : app : log_exception : 1414 : (Process Details : (106907, MainProcess), Thread Details : (140020107859520, Thread-1)) Log : Exception on /api/states/stateList [GET]\nTraceback (most recent call last):\n  File "/home/ai/project/varunClone/venv/lib/python3.9/site-packages/flask/app.py", line 2190, in wsgi_app\n    response = self.full_dispatch_request()\n  File "/home/ai/project/varunClone/venv/lib/python3.9/site-packages/flask/app.py", line 1487, in full_dispatch_request\n    return self.finalize_request(rv)\n  File "/home/ai/project/varunClone/venv/lib/python3.9/site-packages/flask/app.py", line 1506, in finalize_request\n    response = self.make_response(rv)\n  File "/home/ai/project/varunClone/venv/lib/python3.9/site-packages/flask/app.py", line 1801, in make_response\n    raise TypeError(\nTypeError: The view function for 'states_app.stateList' did not return a valid response. The function either returned None or ended without a return statement.
2023-12-08 19:44:37,288 : ERROR : app : log_exception : 1414 : (Process Details : (106907, MainProcess), Thread Details : (140020107859520, Thread-2)) Log : Exception on /api/states/stateList [GET]\nTraceback (most recent call last):\n  File "/home/ai/project/varunClone/venv/lib/python3.9/site-packages/flask/app.py", line 2190, in wsgi_app\n    response = self.full_dispatch_request()\n  File "/home/ai/project/varunClone/venv/lib/python3.9/site-packages/flask/app.py", line 1487, in full_dispatch_request\n    return self.finalize_request(rv)\n  File "/home/ai/project/varunClone/venv/lib/python3.9/site-packages/flask/app.py", line 1506, in finalize_request\n    response = self.make_response(rv)\n  File "/home/ai/project/varunClone/venv/lib/python3.9/site-packages/flask/app.py", line 1801, in make_response\n    raise TypeError(\nTypeError: The view function for 'states_app.stateList' did not return a valid response. The function either returned None or ended without a return statement.
2023-12-13 19:41:23,560 : ERROR : app : log_exception : 1414 : (Process Details : (22058, MainProcess), Thread Details : (139896182539840, Thread-1)) Log : Exception on /api/states/1/party/2/platform/feed [GET]\nTraceback (most recent call last):\n  File "/home/ai/project/varunClone/venv/lib/python3.9/site-packages/sqlalchemy/engine/base.py", line 1965, in _exec_single_context\n    self.dialect.do_execute(\n  File "/home/ai/project/varunClone/venv/lib/python3.9/site-packages/sqlalchemy/engine/default.py", line 921, in do_execute\n    cursor.execute(statement, parameters)\nsqlite3.OperationalError: near "%": syntax error\n\nThe above exception was the direct cause of the following exception:\n\nTraceback (most recent call last):\n  File "/home/ai/project/varunClone/venv/lib/python3.9/site-packages/flask/app.py", line 2190, in wsgi_app\n    response = self.full_dispatch_request()\n  File "/home/ai/project/varunClone/venv/lib/python3.9/site-packages/flask/app.py", line 1486, in full_dispatch_request\n    rv = self.handle_user_exception(e)\n  File "/home/ai/project/varunClone/venv/lib/python3.9/site-packages/flask_cors/extension.py", line 176, in wrapped_function\n    return cors_after_request(app.make_response(f(*args, **kwargs)))\n  File "/home/ai/project/varunClone/venv/lib/python3.9/site-packages/flask/app.py", line 1484, in full_dispatch_request\n    rv = self.dispatch_request()\n  File "/home/ai/project/varunClone/venv/lib/python3.9/site-packages/flask/app.py", line 1469, in dispatch_request\n    return self.ensure_sync(self.view_functions[rule.endpoint])(**view_args)\n  File "/home/ai/project/varunClone/SocialAnalytics/Social/src/blueprints/StatesBlueprint.py", line 128, in list_state\n    result = db.session.execute(query).fetchall()\n  File "/home/ai/project/varunClone/venv/lib/python3.9/site-packages/sqlalchemy/orm/scoping.py", line 738, in execute\n    return self._proxied.execute(\n  File "/home/ai/project/varunClone/venv/lib/python3.9/site-packages/sqlalchemy/orm/session.py", line 2262, in execute\n    return self._execute_internal(\n  File "/home/ai/project/varunClone/venv/lib/python3.9/site-packages/sqlalchemy/orm/session.py", line 2153, in _execute_internal\n    result = conn.execute(\n  File "/home/ai/project/varunClone/venv/lib/python3.9/site-packages/sqlalchemy/engine/base.py", line 1412, in execute\n    return meth(\n  File "/home/ai/project/varunClone/venv/lib/python3.9/site-packages/sqlalchemy/sql/elements.py", line 516, in _execute_on_connection\n    return connection._execute_clauseelement(\n  File "/home/ai/project/varunClone/venv/lib/python3.9/site-packages/sqlalchemy/engine/base.py", line 1635, in _execute_clauseelement\n    ret = self._execute_context(\n  File "/home/ai/project/varunClone/venv/lib/python3.9/site-packages/sqlalchemy/engine/base.py", line 1844, in _execute_context\n    return self._exec_single_context(\n  File "/home/ai/project/varunClone/venv/lib/python3.9/site-packages/sqlalchemy/engine/base.py", line 1984, in _exec_single_context\n    self._handle_dbapi_exception(\n  File "/home/ai/project/varunClone/venv/lib/python3.9/site-packages/sqlalchemy/engine/base.py", line 2339, in _handle_dbapi_exception\n    raise sqlalchemy_exception.with_traceback(exc_info[2]) from e\n  File "/home/ai/project/varunClone/venv/lib/python3.9/site-packages/sqlalchemy/engine/base.py", line 1965, in _exec_single_context\n    self.dialect.do_execute(\n  File "/home/ai/project/varunClone/venv/lib/python3.9/site-packages/sqlalchemy/engine/default.py", line 921, in do_execute\n    cursor.execute(statement, parameters)\nsqlalchemy.exc.OperationalError: (sqlite3.OperationalError) near "%": syntax error\n[SQL:     \n        SELECT * from states WHERE state_code like %1%;\n    ]\n(Background on this error at: https://sqlalche.me/e/20/e3q8)
2023-12-13 19:41:26,591 : ERROR : app : log_exception : 1414 : (Process Details : (22058, MainProcess), Thread Details : (139896182539840, Thread-2)) Log : Exception on /api/states/1/party/2/platform/feed [GET]\nTraceback (most recent call last):\n  File "/home/ai/project/varunClone/venv/lib/python3.9/site-packages/sqlalchemy/engine/base.py", line 1965, in _exec_single_context\n    self.dialect.do_execute(\n  File "/home/ai/project/varunClone/venv/lib/python3.9/site-packages/sqlalchemy/engine/default.py", line 921, in do_execute\n    cursor.execute(statement, parameters)\nsqlite3.OperationalError: near "%": syntax error\n\nThe above exception was the direct cause of the following exception:\n\nTraceback (most recent call last):\n  File "/home/ai/project/varunClone/venv/lib/python3.9/site-packages/flask/app.py", line 2190, in wsgi_app\n    response = self.full_dispatch_request()\n  File "/home/ai/project/varunClone/venv/lib/python3.9/site-packages/flask/app.py", line 1486, in full_dispatch_request\n    rv = self.handle_user_exception(e)\n  File "/home/ai/project/varunClone/venv/lib/python3.9/site-packages/flask_cors/extension.py", line 176, in wrapped_function\n    return cors_after_request(app.make_response(f(*args, **kwargs)))\n  File "/home/ai/project/varunClone/venv/lib/python3.9/site-packages/flask/app.py", line 1484, in full_dispatch_request\n    rv = self.dispatch_request()\n  File "/home/ai/project/varunClone/venv/lib/python3.9/site-packages/flask/app.py", line 1469, in dispatch_request\n    return self.ensure_sync(self.view_functions[rule.endpoint])(**view_args)\n  File "/home/ai/project/varunClone/SocialAnalytics/Social/src/blueprints/StatesBlueprint.py", line 128, in list_state\n    result = db.session.execute(query).fetchall()\n  File "/home/ai/project/varunClone/venv/lib/python3.9/site-packages/sqlalchemy/orm/scoping.py", line 738, in execute\n    return self._proxied.execute(\n  File "/home/ai/project/varunClone/venv/lib/python3.9/site-packages/sqlalchemy/orm/session.py", line 2262, in execute\n    return self._execute_internal(\n  File "/home/ai/project/varunClone/venv/lib/python3.9/site-packages/sqlalchemy/orm/session.py", line 2153, in _execute_internal\n    result = conn.execute(\n  File "/home/ai/project/varunClone/venv/lib/python3.9/site-packages/sqlalchemy/engine/base.py", line 1412, in execute\n    return meth(\n  File "/home/ai/project/varunClone/venv/lib/python3.9/site-packages/sqlalchemy/sql/elements.py", line 516, in _execute_on_connection\n    return connection._execute_clauseelement(\n  File "/home/ai/project/varunClone/venv/lib/python3.9/site-packages/sqlalchemy/engine/base.py", line 1635, in _execute_clauseelement\n    ret = self._execute_context(\n  File "/home/ai/project/varunClone/venv/lib/python3.9/site-packages/sqlalchemy/engine/base.py", line 1844, in _execute_context\n    return self._exec_single_context(\n  File "/home/ai/project/varunClone/venv/lib/python3.9/site-packages/sqlalchemy/engine/base.py", line 1984, in _exec_single_context\n    self._handle_dbapi_exception(\n  File "/home/ai/project/varunClone/venv/lib/python3.9/site-packages/sqlalchemy/engine/base.py", line 2339, in _handle_dbapi_exception\n    raise sqlalchemy_exception.with_traceback(exc_info[2]) from e\n  File "/home/ai/project/varunClone/venv/lib/python3.9/site-packages/sqlalchemy/engine/base.py", line 1965, in _exec_single_context\n    self.dialect.do_execute(\n  File "/home/ai/project/varunClone/venv/lib/python3.9/site-packages/sqlalchemy/engine/default.py", line 921, in do_execute\n    cursor.execute(statement, parameters)\nsqlalchemy.exc.OperationalError: (sqlite3.OperationalError) near "%": syntax error\n[SQL:     \n        SELECT * from states WHERE state_code like %1%;\n    ]\n(Background on this error at: https://sqlalche.me/e/20/e3q8)
2023-12-13 19:57:13,177 : ERROR : app : log_exception : 1414 : (Process Details : (25792, MainProcess), Thread Details : (139837615789632, Thread-1)) Log : Exception on /api/states/Andhra Pradesh/party/2/platform/feed [GET]\nTraceback (most recent call last):\n  File "/home/ai/project/varunClone/venv/lib/python3.9/site-packages/sqlalchemy/engine/base.py", line 1965, in _exec_single_context\n    self.dialect.do_execute(\n  File "/home/ai/project/varunClone/venv/lib/python3.9/site-packages/sqlalchemy/engine/default.py", line 921, in do_execute\n    cursor.execute(statement, parameters)\nsqlite3.OperationalError: near "%": syntax error\n\nThe above exception was the direct cause of the following exception:\n\nTraceback (most recent call last):\n  File "/home/ai/project/varunClone/venv/lib/python3.9/site-packages/flask/app.py", line 2190, in wsgi_app\n    response = self.full_dispatch_request()\n  File "/home/ai/project/varunClone/venv/lib/python3.9/site-packages/flask/app.py", line 1486, in full_dispatch_request\n    rv = self.handle_user_exception(e)\n  File "/home/ai/project/varunClone/venv/lib/python3.9/site-packages/flask_cors/extension.py", line 176, in wrapped_function\n    return cors_after_request(app.make_response(f(*args, **kwargs)))\n  File "/home/ai/project/varunClone/venv/lib/python3.9/site-packages/flask/app.py", line 1484, in full_dispatch_request\n    rv = self.dispatch_request()\n  File "/home/ai/project/varunClone/venv/lib/python3.9/site-packages/flask/app.py", line 1469, in dispatch_request\n    return self.ensure_sync(self.view_functions[rule.endpoint])(**view_args)\n  File "/home/ai/project/varunClone/SocialAnalytics/Social/src/blueprints/StatesBlueprint.py", line 128, in list_state\n    result = db.session.execute(query).fetchall()\n  File "/home/ai/project/varunClone/venv/lib/python3.9/site-packages/sqlalchemy/orm/scoping.py", line 738, in execute\n    return self._proxied.execute(\n  File "/home/ai/project/varunClone/venv/lib/python3.9/site-packages/sqlalchemy/orm/session.py", line 2262, in execute\n    return self._execute_internal(\n  File "/home/ai/project/varunClone/venv/lib/python3.9/site-packages/sqlalchemy/orm/session.py", line 2153, in _execute_internal\n    result = conn.execute(\n  File "/home/ai/project/varunClone/venv/lib/python3.9/site-packages/sqlalchemy/engine/base.py", line 1412, in execute\n    return meth(\n  File "/home/ai/project/varunClone/venv/lib/python3.9/site-packages/sqlalchemy/sql/elements.py", line 516, in _execute_on_connection\n    return connection._execute_clauseelement(\n  File "/home/ai/project/varunClone/venv/lib/python3.9/site-packages/sqlalchemy/engine/base.py", line 1635, in _execute_clauseelement\n    ret = self._execute_context(\n  File "/home/ai/project/varunClone/venv/lib/python3.9/site-packages/sqlalchemy/engine/base.py", line 1844, in _execute_context\n    return self._exec_single_context(\n  File "/home/ai/project/varunClone/venv/lib/python3.9/site-packages/sqlalchemy/engine/base.py", line 1984, in _exec_single_context\n    self._handle_dbapi_exception(\n  File "/home/ai/project/varunClone/venv/lib/python3.9/site-packages/sqlalchemy/engine/base.py", line 2339, in _handle_dbapi_exception\n    raise sqlalchemy_exception.with_traceback(exc_info[2]) from e\n  File "/home/ai/project/varunClone/venv/lib/python3.9/site-packages/sqlalchemy/engine/base.py", line 1965, in _exec_single_context\n    self.dialect.do_execute(\n  File "/home/ai/project/varunClone/venv/lib/python3.9/site-packages/sqlalchemy/engine/default.py", line 921, in do_execute\n    cursor.execute(statement, parameters)\nsqlalchemy.exc.OperationalError: (sqlite3.OperationalError) near "%": syntax error\n[SQL:     \n        SELECT * from states WHERE state_code like %Andhra Pradesh%;\n    ]\n(Background on this error at: https://sqlalche.me/e/20/e3q8)
2023-12-14 16:31:35,883 : ERROR : app : log_exception : 1414 : (Process Details : (18269, MainProcess), Thread Details : (139974294349376, Thread-1)) Log : Exception on /api/states/Andhra Pradesh/party/2/platform/feed [GET]\nTraceback (most recent call last):\n  File "/home/ai/project/varunClone/venv/lib/python3.9/site-packages/sqlalchemy/engine/base.py", line 1965, in _exec_single_context\n    self.dialect.do_execute(\n  File "/home/ai/project/varunClone/venv/lib/python3.9/site-packages/sqlalchemy/engine/default.py", line 921, in do_execute\n    cursor.execute(statement, parameters)\nsqlite3.OperationalError: no such table: plateform_users\n\nThe above exception was the direct cause of the following exception:\n\nTraceback (most recent call last):\n  File "/home/ai/project/varunClone/venv/lib/python3.9/site-packages/flask/app.py", line 2190, in wsgi_app\n    response = self.full_dispatch_request()\n  File "/home/ai/project/varunClone/venv/lib/python3.9/site-packages/flask/app.py", line 1486, in full_dispatch_request\n    rv = self.handle_user_exception(e)\n  File "/home/ai/project/varunClone/venv/lib/python3.9/site-packages/flask_cors/extension.py", line 176, in wrapped_function\n    return cors_after_request(app.make_response(f(*args, **kwargs)))\n  File "/home/ai/project/varunClone/venv/lib/python3.9/site-packages/flask/app.py", line 1484, in full_dispatch_request\n    rv = self.dispatch_request()\n  File "/home/ai/project/varunClone/venv/lib/python3.9/site-packages/flask/app.py", line 1469, in dispatch_request\n    return self.ensure_sync(self.view_functions[rule.endpoint])(**view_args)\n  File "/home/ai/project/varunClone/SocialAnalytics/Social/src/blueprints/StatesBlueprint.py", line 131, in list_state\n    result = db.session.execute(query).fetchall()\n  File "/home/ai/project/varunClone/venv/lib/python3.9/site-packages/sqlalchemy/orm/scoping.py", line 738, in execute\n    return self._proxied.execute(\n  File "/home/ai/project/varunClone/venv/lib/python3.9/site-packages/sqlalchemy/orm/session.py", line 2262, in execute\n    return self._execute_internal(\n  File "/home/ai/project/varunClone/venv/lib/python3.9/site-packages/sqlalchemy/orm/session.py", line 2153, in _execute_internal\n    result = conn.execute(\n  File "/home/ai/project/varunClone/venv/lib/python3.9/site-packages/sqlalchemy/engine/base.py", line 1412, in execute\n    return meth(\n  File "/home/ai/project/varunClone/venv/lib/python3.9/site-packages/sqlalchemy/sql/elements.py", line 516, in _execute_on_connection\n    return connection._execute_clauseelement(\n  File "/home/ai/project/varunClone/venv/lib/python3.9/site-packages/sqlalchemy/engine/base.py", line 1635, in _execute_clauseelement\n    ret = self._execute_context(\n  File "/home/ai/project/varunClone/venv/lib/python3.9/site-packages/sqlalchemy/engine/base.py", line 1844, in _execute_context\n    return self._exec_single_context(\n  File "/home/ai/project/varunClone/venv/lib/python3.9/site-packages/sqlalchemy/engine/base.py", line 1984, in _exec_single_context\n    self._handle_dbapi_exception(\n  File "/home/ai/project/varunClone/venv/lib/python3.9/site-packages/sqlalchemy/engine/base.py", line 2339, in _handle_dbapi_exception\n    raise sqlalchemy_exception.with_traceback(exc_info[2]) from e\n  File "/home/ai/project/varunClone/venv/lib/python3.9/site-packages/sqlalchemy/engine/base.py", line 1965, in _exec_single_context\n    self.dialect.do_execute(\n  File "/home/ai/project/varunClone/venv/lib/python3.9/site-packages/sqlalchemy/engine/default.py", line 921, in do_execute\n    cursor.execute(statement, parameters)\nsqlalchemy.exc.OperationalError: (sqlite3.OperationalError) no such table: plateform_users\n[SQL:     \n        SELECT * from plateform_users WHERE state_code like '%Andhra Pradesh%';\n    ]\n(Background on this error at: https://sqlalche.me/e/20/e3q8)
2023-12-14 16:46:42,753 : ERROR : app : log_exception : 1414 : (Process Details : (18269, MainProcess), Thread Details : (139974294349376, Thread-3)) Log : Exception on /api/states/Andhra Pradesh/party/2/platform/feed [GET]\nTraceback (most recent call last):\n  File "/home/ai/project/varunClone/venv/lib/python3.9/site-packages/sqlalchemy/engine/base.py", line 1965, in _exec_single_context\n    self.dialect.do_execute(\n  File "/home/ai/project/varunClone/venv/lib/python3.9/site-packages/sqlalchemy/engine/default.py", line 921, in do_execute\n    cursor.execute(statement, parameters)\nsqlite3.OperationalError: no such table: plateform_users\n\nThe above exception was the direct cause of the following exception:\n\nTraceback (most recent call last):\n  File "/home/ai/project/varunClone/venv/lib/python3.9/site-packages/flask/app.py", line 2190, in wsgi_app\n    response = self.full_dispatch_request()\n  File "/home/ai/project/varunClone/venv/lib/python3.9/site-packages/flask/app.py", line 1486, in full_dispatch_request\n    rv = self.handle_user_exception(e)\n  File "/home/ai/project/varunClone/venv/lib/python3.9/site-packages/flask_cors/extension.py", line 176, in wrapped_function\n    return cors_after_request(app.make_response(f(*args, **kwargs)))\n  File "/home/ai/project/varunClone/venv/lib/python3.9/site-packages/flask/app.py", line 1484, in full_dispatch_request\n    rv = self.dispatch_request()\n  File "/home/ai/project/varunClone/venv/lib/python3.9/site-packages/flask/app.py", line 1469, in dispatch_request\n    return self.ensure_sync(self.view_functions[rule.endpoint])(**view_args)\n  File "/home/ai/project/varunClone/SocialAnalytics/Social/src/blueprints/StatesBlueprint.py", line 131, in list_state\n    result = db.session.execute(query).fetchall()\n  File "/home/ai/project/varunClone/venv/lib/python3.9/site-packages/sqlalchemy/orm/scoping.py", line 738, in execute\n    return self._proxied.execute(\n  File "/home/ai/project/varunClone/venv/lib/python3.9/site-packages/sqlalchemy/orm/session.py", line 2262, in execute\n    return self._execute_internal(\n  File "/home/ai/project/varunClone/venv/lib/python3.9/site-packages/sqlalchemy/orm/session.py", line 2153, in _execute_internal\n    result = conn.execute(\n  File "/home/ai/project/varunClone/venv/lib/python3.9/site-packages/sqlalchemy/engine/base.py", line 1412, in execute\n    return meth(\n  File "/home/ai/project/varunClone/venv/lib/python3.9/site-packages/sqlalchemy/sql/elements.py", line 516, in _execute_on_connection\n    return connection._execute_clauseelement(\n  File "/home/ai/project/varunClone/venv/lib/python3.9/site-packages/sqlalchemy/engine/base.py", line 1635, in _execute_clauseelement\n    ret = self._execute_context(\n  File "/home/ai/project/varunClone/venv/lib/python3.9/site-packages/sqlalchemy/engine/base.py", line 1844, in _execute_context\n    return self._exec_single_context(\n  File "/home/ai/project/varunClone/venv/lib/python3.9/site-packages/sqlalchemy/engine/base.py", line 1984, in _exec_single_context\n    self._handle_dbapi_exception(\n  File "/home/ai/project/varunClone/venv/lib/python3.9/site-packages/sqlalchemy/engine/base.py", line 2339, in _handle_dbapi_exception\n    raise sqlalchemy_exception.with_traceback(exc_info[2]) from e\n  File "/home/ai/project/varunClone/venv/lib/python3.9/site-packages/sqlalchemy/engine/base.py", line 1965, in _exec_single_context\n    self.dialect.do_execute(\n  File "/home/ai/project/varunClone/venv/lib/python3.9/site-packages/sqlalchemy/engine/default.py", line 921, in do_execute\n    cursor.execute(statement, parameters)\nsqlalchemy.exc.OperationalError: (sqlite3.OperationalError) no such table: plateform_users\n[SQL:     \n        SELECT * from plateform_users WHERE state_code like '%Andhra Pradesh%';\n    ]\n(Background on this error at: https://sqlalche.me/e/20/e3q8)
2023-12-14 18:41:14,068 : ERROR : app : log_exception : 1414 : (Process Details : (31740, MainProcess), Thread Details : (139680744998464, Thread-1)) Log : Exception on /api/states/Andhra Pradesh/party/bjp/platform/feed [GET]\nTraceback (most recent call last):\n  File "/home/ai/project/varunClone/venv/lib/python3.9/site-packages/sqlalchemy/engine/base.py", line 1965, in _exec_single_context\n    self.dialect.do_execute(\n  File "/home/ai/project/varunClone/venv/lib/python3.9/site-packages/sqlalchemy/engine/default.py", line 921, in do_execute\n    cursor.execute(statement, parameters)\nsqlite3.OperationalError: near "WHERE": syntax error\n\nThe above exception was the direct cause of the following exception:\n\nTraceback (most recent call last):\n  File "/home/ai/project/varunClone/venv/lib/python3.9/site-packages/flask/app.py", line 2190, in wsgi_app\n    response = self.full_dispatch_request()\n  File "/home/ai/project/varunClone/venv/lib/python3.9/site-packages/flask/app.py", line 1486, in full_dispatch_request\n    rv = self.handle_user_exception(e)\n  File "/home/ai/project/varunClone/venv/lib/python3.9/site-packages/flask_cors/extension.py", line 176, in wrapped_function\n    return cors_after_request(app.make_response(f(*args, **kwargs)))\n  File "/home/ai/project/varunClone/venv/lib/python3.9/site-packages/flask/app.py", line 1484, in full_dispatch_request\n    rv = self.dispatch_request()\n  File "/home/ai/project/varunClone/venv/lib/python3.9/site-packages/flask/app.py", line 1469, in dispatch_request\n    return self.ensure_sync(self.view_functions[rule.endpoint])(**view_args)\n  File "/home/ai/project/varunClone/SocialAnalytics/Social/src/blueprints/StatesBlueprint.py", line 140, in list_state\n    result = db.session.execute(query).fetchall()\n  File "/home/ai/project/varunClone/venv/lib/python3.9/site-packages/sqlalchemy/orm/scoping.py", line 738, in execute\n    return self._proxied.execute(\n  File "/home/ai/project/varunClone/venv/lib/python3.9/site-packages/sqlalchemy/orm/session.py", line 2262, in execute\n    return self._execute_internal(\n  File "/home/ai/project/varunClone/venv/lib/python3.9/site-packages/sqlalchemy/orm/session.py", line 2153, in _execute_internal\n    result = conn.execute(\n  File "/home/ai/project/varunClone/venv/lib/python3.9/site-packages/sqlalchemy/engine/base.py", line 1412, in execute\n    return meth(\n  File "/home/ai/project/varunClone/venv/lib/python3.9/site-packages/sqlalchemy/sql/elements.py", line 516, in _execute_on_connection\n    return connection._execute_clauseelement(\n  File "/home/ai/project/varunClone/venv/lib/python3.9/site-packages/sqlalchemy/engine/base.py", line 1635, in _execute_clauseelement\n    ret = self._execute_context(\n  File "/home/ai/project/varunClone/venv/lib/python3.9/site-packages/sqlalchemy/engine/base.py", line 1844, in _execute_context\n    return self._exec_single_context(\n  File "/home/ai/project/varunClone/venv/lib/python3.9/site-packages/sqlalchemy/engine/base.py", line 1984, in _exec_single_context\n    self._handle_dbapi_exception(\n  File "/home/ai/project/varunClone/venv/lib/python3.9/site-packages/sqlalchemy/engine/base.py", line 2339, in _handle_dbapi_exception\n    raise sqlalchemy_exception.with_traceback(exc_info[2]) from e\n  File "/home/ai/project/varunClone/venv/lib/python3.9/site-packages/sqlalchemy/engine/base.py", line 1965, in _exec_single_context\n    self.dialect.do_execute(\n  File "/home/ai/project/varunClone/venv/lib/python3.9/site-packages/sqlalchemy/engine/default.py", line 921, in do_execute\n    cursor.execute(statement, parameters)\nsqlalchemy.exc.OperationalError: (sqlite3.OperationalError) near "WHERE": syntax error\n[SQL:     \n   \n        SELECT count(comments.classification) as comment,comments.*, platform_users.*,\n        sum(CASE WHEN classification=='Pro Government' THEN 1 ELSE 0 END) as proGov,\n        sum(CASE WHEN classification=='Anti Government' THEN 1 ELSE 0 END) as antiGov,\n        count(DISTINCT comments.post_id) as totalPost\n        FROM platform_users\n            INNER JOIN comments\n                ON comments.email_id = platform_users.email_id\n                GROUP by platform_users.platform_name\n                WHERE state_code like '%Andhra Pradesh%'\n\n    ]\n(Background on this error at: https://sqlalche.me/e/20/e3q8)
2023-12-14 18:41:17,013 : ERROR : app : log_exception : 1414 : (Process Details : (31740, MainProcess), Thread Details : (139680744998464, Thread-2)) Log : Exception on /api/states/Andhra Pradesh/party/bjp/platform/feed [GET]\nTraceback (most recent call last):\n  File "/home/ai/project/varunClone/venv/lib/python3.9/site-packages/sqlalchemy/engine/base.py", line 1965, in _exec_single_context\n    self.dialect.do_execute(\n  File "/home/ai/project/varunClone/venv/lib/python3.9/site-packages/sqlalchemy/engine/default.py", line 921, in do_execute\n    cursor.execute(statement, parameters)\nsqlite3.OperationalError: near "WHERE": syntax error\n\nThe above exception was the direct cause of the following exception:\n\nTraceback (most recent call last):\n  File "/home/ai/project/varunClone/venv/lib/python3.9/site-packages/flask/app.py", line 2190, in wsgi_app\n    response = self.full_dispatch_request()\n  File "/home/ai/project/varunClone/venv/lib/python3.9/site-packages/flask/app.py", line 1486, in full_dispatch_request\n    rv = self.handle_user_exception(e)\n  File "/home/ai/project/varunClone/venv/lib/python3.9/site-packages/flask_cors/extension.py", line 176, in wrapped_function\n    return cors_after_request(app.make_response(f(*args, **kwargs)))\n  File "/home/ai/project/varunClone/venv/lib/python3.9/site-packages/flask/app.py", line 1484, in full_dispatch_request\n    rv = self.dispatch_request()\n  File "/home/ai/project/varunClone/venv/lib/python3.9/site-packages/flask/app.py", line 1469, in dispatch_request\n    return self.ensure_sync(self.view_functions[rule.endpoint])(**view_args)\n  File "/home/ai/project/varunClone/SocialAnalytics/Social/src/blueprints/StatesBlueprint.py", line 140, in list_state\n    result = db.session.execute(query).fetchall()\n  File "/home/ai/project/varunClone/venv/lib/python3.9/site-packages/sqlalchemy/orm/scoping.py", line 738, in execute\n    return self._proxied.execute(\n  File "/home/ai/project/varunClone/venv/lib/python3.9/site-packages/sqlalchemy/orm/session.py", line 2262, in execute\n    return self._execute_internal(\n  File "/home/ai/project/varunClone/venv/lib/python3.9/site-packages/sqlalchemy/orm/session.py", line 2153, in _execute_internal\n    result = conn.execute(\n  File "/home/ai/project/varunClone/venv/lib/python3.9/site-packages/sqlalchemy/engine/base.py", line 1412, in execute\n    return meth(\n  File "/home/ai/project/varunClone/venv/lib/python3.9/site-packages/sqlalchemy/sql/elements.py", line 516, in _execute_on_connection\n    return connection._execute_clauseelement(\n  File "/home/ai/project/varunClone/venv/lib/python3.9/site-packages/sqlalchemy/engine/base.py", line 1635, in _execute_clauseelement\n    ret = self._execute_context(\n  File "/home/ai/project/varunClone/venv/lib/python3.9/site-packages/sqlalchemy/engine/base.py", line 1844, in _execute_context\n    return self._exec_single_context(\n  File "/home/ai/project/varunClone/venv/lib/python3.9/site-packages/sqlalchemy/engine/base.py", line 1984, in _exec_single_context\n    self._handle_dbapi_exception(\n  File "/home/ai/project/varunClone/venv/lib/python3.9/site-packages/sqlalchemy/engine/base.py", line 2339, in _handle_dbapi_exception\n    raise sqlalchemy_exception.with_traceback(exc_info[2]) from e\n  File "/home/ai/project/varunClone/venv/lib/python3.9/site-packages/sqlalchemy/engine/base.py", line 1965, in _exec_single_context\n    self.dialect.do_execute(\n  File "/home/ai/project/varunClone/venv/lib/python3.9/site-packages/sqlalchemy/engine/default.py", line 921, in do_execute\n    cursor.execute(statement, parameters)\nsqlalchemy.exc.OperationalError: (sqlite3.OperationalError) near "WHERE": syntax error\n[SQL:     \n   \n        SELECT count(comments.classification) as comment,comments.*, platform_users.*,\n        sum(CASE WHEN classification=='Pro Government' THEN 1 ELSE 0 END) as proGov,\n        sum(CASE WHEN classification=='Anti Government' THEN 1 ELSE 0 END) as antiGov,\n        count(DISTINCT comments.post_id) as totalPost\n        FROM platform_users\n            INNER JOIN comments\n                ON comments.email_id = platform_users.email_id\n                GROUP by platform_users.platform_name\n                WHERE state_code like '%Andhra Pradesh%'\n\n    ]\n(Background on this error at: https://sqlalche.me/e/20/e3q8)
2023-12-14 18:47:11,195 : ERROR : app : log_exception : 1414 : (Process Details : (32343, MainProcess), Thread Details : (140682107106880, Thread-1)) Log : Exception on /api/states/Andhra Pradesh/party/bjp/platform/feed [GET]\nTraceback (most recent call last):\n  File "/home/ai/project/varunClone/venv/lib/python3.9/site-packages/flask/app.py", line 2190, in wsgi_app\n    response = self.full_dispatch_request()\n  File "/home/ai/project/varunClone/venv/lib/python3.9/site-packages/flask/app.py", line 1487, in full_dispatch_request\n    return self.finalize_request(rv)\n  File "/home/ai/project/varunClone/venv/lib/python3.9/site-packages/flask/app.py", line 1506, in finalize_request\n    response = self.make_response(rv)\n  File "/home/ai/project/varunClone/venv/lib/python3.9/site-packages/flask/app.py", line 1801, in make_response\n    raise TypeError(\nTypeError: The view function for 'states_app.list_state' did not return a valid response. The function either returned None or ended without a return statement.
2023-12-14 18:48:02,906 : ERROR : app : log_exception : 1414 : (Process Details : (32433, MainProcess), Thread Details : (139975303530048, Thread-1)) Log : Exception on /api/states/Andhra Pradesh/party/bjp/platform/feed [GET]\nTraceback (most recent call last):\n  File "/home/ai/project/varunClone/venv/lib/python3.9/site-packages/flask/app.py", line 2190, in wsgi_app\n    response = self.full_dispatch_request()\n  File "/home/ai/project/varunClone/venv/lib/python3.9/site-packages/flask/app.py", line 1487, in full_dispatch_request\n    return self.finalize_request(rv)\n  File "/home/ai/project/varunClone/venv/lib/python3.9/site-packages/flask/app.py", line 1506, in finalize_request\n    response = self.make_response(rv)\n  File "/home/ai/project/varunClone/venv/lib/python3.9/site-packages/flask/app.py", line 1801, in make_response\n    raise TypeError(\nTypeError: The view function for 'states_app.list_state' did not return a valid response. The function either returned None or ended without a return statement.
2023-12-14 18:52:25,695 : ERROR : app : log_exception : 1414 : (Process Details : (32812, MainProcess), Thread Details : (139771803489856, Thread-1)) Log : Exception on /api/states/Andhra Pradesh/party/bjp/platform/feed [GET]\nTraceback (most recent call last):\n  File "/home/ai/project/varunClone/venv/lib/python3.9/site-packages/flask/app.py", line 2190, in wsgi_app\n    response = self.full_dispatch_request()\n  File "/home/ai/project/varunClone/venv/lib/python3.9/site-packages/flask/app.py", line 1486, in full_dispatch_request\n    rv = self.handle_user_exception(e)\n  File "/home/ai/project/varunClone/venv/lib/python3.9/site-packages/flask_cors/extension.py", line 176, in wrapped_function\n    return cors_after_request(app.make_response(f(*args, **kwargs)))\n  File "/home/ai/project/varunClone/venv/lib/python3.9/site-packages/flask/app.py", line 1484, in full_dispatch_request\n    rv = self.dispatch_request()\n  File "/home/ai/project/varunClone/venv/lib/python3.9/site-packages/flask/app.py", line 1469, in dispatch_request\n    return self.ensure_sync(self.view_functions[rule.endpoint])(**view_args)\n  File "/home/ai/project/varunClone/SocialAnalytics/Social/src/blueprints/StatesBlueprint.py", line 131, in list_state\n    print(result[0]['totalPost'])\n  File "lib/sqlalchemy/cyextension/resultproxy.pyx", line 48, in sqlalchemy.cyextension.resultproxy.BaseRow.__getitem__\nTypeError: tuple indices must be integers or slices, not str
2023-12-14 18:53:08,843 : ERROR : app : log_exception : 1414 : (Process Details : (32897, MainProcess), Thread Details : (139914911544896, Thread-1)) Log : Exception on /api/states/Andhra Pradesh/party/bjp/platform/feed [GET]\nTraceback (most recent call last):\n  File "/home/ai/project/varunClone/venv/lib/python3.9/site-packages/flask/app.py", line 2190, in wsgi_app\n    response = self.full_dispatch_request()\n  File "/home/ai/project/varunClone/venv/lib/python3.9/site-packages/flask/app.py", line 1486, in full_dispatch_request\n    rv = self.handle_user_exception(e)\n  File "/home/ai/project/varunClone/venv/lib/python3.9/site-packages/flask_cors/extension.py", line 176, in wrapped_function\n    return cors_after_request(app.make_response(f(*args, **kwargs)))\n  File "/home/ai/project/varunClone/venv/lib/python3.9/site-packages/flask/app.py", line 1484, in full_dispatch_request\n    rv = self.dispatch_request()\n  File "/home/ai/project/varunClone/venv/lib/python3.9/site-packages/flask/app.py", line 1469, in dispatch_request\n    return self.ensure_sync(self.view_functions[rule.endpoint])(**view_args)\n  File "/home/ai/project/varunClone/SocialAnalytics/Social/src/blueprints/StatesBlueprint.py", line 131, in list_state\n    print(result[0]['totalPost'])\n  File "lib/sqlalchemy/cyextension/resultproxy.pyx", line 48, in sqlalchemy.cyextension.resultproxy.BaseRow.__getitem__\nTypeError: tuple indices must be integers or slices, not str
2023-12-14 18:53:29,998 : ERROR : app : log_exception : 1414 : (Process Details : (32955, MainProcess), Thread Details : (140326532261440, Thread-1)) Log : Exception on /api/states/Andhra Pradesh/party/bjp/platform/feed [GET]\nTraceback (most recent call last):\n  File "/home/ai/project/varunClone/venv/lib/python3.9/site-packages/flask/app.py", line 2190, in wsgi_app\n    response = self.full_dispatch_request()\n  File "/home/ai/project/varunClone/venv/lib/python3.9/site-packages/flask/app.py", line 1486, in full_dispatch_request\n    rv = self.handle_user_exception(e)\n  File "/home/ai/project/varunClone/venv/lib/python3.9/site-packages/flask_cors/extension.py", line 176, in wrapped_function\n    return cors_after_request(app.make_response(f(*args, **kwargs)))\n  File "/home/ai/project/varunClone/venv/lib/python3.9/site-packages/flask/app.py", line 1484, in full_dispatch_request\n    rv = self.dispatch_request()\n  File "/home/ai/project/varunClone/venv/lib/python3.9/site-packages/flask/app.py", line 1469, in dispatch_request\n    return self.ensure_sync(self.view_functions[rule.endpoint])(**view_args)\n  File "/home/ai/project/varunClone/SocialAnalytics/Social/src/blueprints/StatesBlueprint.py", line 131, in list_state\n    print(result['totalPost'])\nTypeError: list indices must be integers or slices, not str
2023-12-14 18:54:00,972 : ERROR : app : log_exception : 1414 : (Process Details : (33023, MainProcess), Thread Details : (140374788539968, Thread-1)) Log : Exception on /api/states/Andhra Pradesh/party/bjp/platform/feed [GET]\nTraceback (most recent call last):\n  File "/home/ai/project/varunClone/venv/lib/python3.9/site-packages/flask/app.py", line 2190, in wsgi_app\n    response = self.full_dispatch_request()\n  File "/home/ai/project/varunClone/venv/lib/python3.9/site-packages/flask/app.py", line 1487, in full_dispatch_request\n    return self.finalize_request(rv)\n  File "/home/ai/project/varunClone/venv/lib/python3.9/site-packages/flask/app.py", line 1506, in finalize_request\n    response = self.make_response(rv)\n  File "/home/ai/project/varunClone/venv/lib/python3.9/site-packages/flask/app.py", line 1801, in make_response\n    raise TypeError(\nTypeError: The view function for 'states_app.list_state' did not return a valid response. The function either returned None or ended without a return statement.
2023-12-14 18:58:33,510 : ERROR : app : log_exception : 1414 : (Process Details : (33451, MainProcess), Thread Details : (140687231546944, Thread-1)) Log : Exception on /api/states/Andhra Pradesh/party/bjp/platform/feed [GET]\nTraceback (most recent call last):\n  File "/home/ai/project/varunClone/venv/lib/python3.9/site-packages/sqlalchemy/engine/base.py", line 1965, in _exec_single_context\n    self.dialect.do_execute(\n  File "/home/ai/project/varunClone/venv/lib/python3.9/site-packages/sqlalchemy/engine/default.py", line 921, in do_execute\n    cursor.execute(statement, parameters)\nsqlite3.OperationalError: near "FROM": syntax error\n\nThe above exception was the direct cause of the following exception:\n\nTraceback (most recent call last):\n  File "/home/ai/project/varunClone/venv/lib/python3.9/site-packages/flask/app.py", line 2190, in wsgi_app\n    response = self.full_dispatch_request()\n  File "/home/ai/project/varunClone/venv/lib/python3.9/site-packages/flask/app.py", line 1486, in full_dispatch_request\n    rv = self.handle_user_exception(e)\n  File "/home/ai/project/varunClone/venv/lib/python3.9/site-packages/flask_cors/extension.py", line 176, in wrapped_function\n    return cors_after_request(app.make_response(f(*args, **kwargs)))\n  File "/home/ai/project/varunClone/venv/lib/python3.9/site-packages/flask/app.py", line 1484, in full_dispatch_request\n    rv = self.dispatch_request()\n  File "/home/ai/project/varunClone/venv/lib/python3.9/site-packages/flask/app.py", line 1469, in dispatch_request\n    return self.ensure_sync(self.view_functions[rule.endpoint])(**view_args)\n  File "/home/ai/project/varunClone/SocialAnalytics/Social/src/blueprints/StatesBlueprint.py", line 131, in list_state\n    result = db.session.execute(query).fetchall()\n  File "/home/ai/project/varunClone/venv/lib/python3.9/site-packages/sqlalchemy/orm/scoping.py", line 738, in execute\n    return self._proxied.execute(\n  File "/home/ai/project/varunClone/venv/lib/python3.9/site-packages/sqlalchemy/orm/session.py", line 2262, in execute\n    return self._execute_internal(\n  File "/home/ai/project/varunClone/venv/lib/python3.9/site-packages/sqlalchemy/orm/session.py", line 2153, in _execute_internal\n    result = conn.execute(\n  File "/home/ai/project/varunClone/venv/lib/python3.9/site-packages/sqlalchemy/engine/base.py", line 1412, in execute\n    return meth(\n  File "/home/ai/project/varunClone/venv/lib/python3.9/site-packages/sqlalchemy/sql/elements.py", line 516, in _execute_on_connection\n    return connection._execute_clauseelement(\n  File "/home/ai/project/varunClone/venv/lib/python3.9/site-packages/sqlalchemy/engine/base.py", line 1635, in _execute_clauseelement\n    ret = self._execute_context(\n  File "/home/ai/project/varunClone/venv/lib/python3.9/site-packages/sqlalchemy/engine/base.py", line 1844, in _execute_context\n    return self._exec_single_context(\n  File "/home/ai/project/varunClone/venv/lib/python3.9/site-packages/sqlalchemy/engine/base.py", line 1984, in _exec_single_context\n    self._handle_dbapi_exception(\n  File "/home/ai/project/varunClone/venv/lib/python3.9/site-packages/sqlalchemy/engine/base.py", line 2339, in _handle_dbapi_exception\n    raise sqlalchemy_exception.with_traceback(exc_info[2]) from e\n  File "/home/ai/project/varunClone/venv/lib/python3.9/site-packages/sqlalchemy/engine/base.py", line 1965, in _exec_single_context\n    self.dialect.do_execute(\n  File "/home/ai/project/varunClone/venv/lib/python3.9/site-packages/sqlalchemy/engine/default.py", line 921, in do_execute\n    cursor.execute(statement, parameters)\nsqlalchemy.exc.OperationalError: (sqlite3.OperationalError) near "FROM": syntax error\n[SQL:     \n\n        SELECT count(comments.classification) as comment,\n        sum(CASE WHEN classification=='Pro Government' THEN 1 ELSE 0 END) as proGov,\n        sum(CASE WHEN classification=='Anti Government' THEN 1 ELSE 0 END) as antiGov,\n        count(DISTINCT comments.post_id) as totalPost,\n        comments.*, platform_users.*,\n        FROM platform_users\n            INNER JOIN comments\n                ON comments.email_id = platform_users.email_id\n                WHERE state_code like '%Andhra Pradesh%'\n                GROUP by platform_users.platform_name\n\n    ]\n(Background on this error at: https://sqlalche.me/e/20/e3q8)
2023-12-14 19:00:48,437 : ERROR : app : log_exception : 1414 : (Process Details : (33867, MainProcess), Thread Details : (139772190164544, Thread-1)) Log : Exception on /api/states/Andhra Pradesh/party/bjp/platform/feed [GET]\nTraceback (most recent call last):\n  File "/home/ai/project/varunClone/venv/lib/python3.9/site-packages/flask/app.py", line 2190, in wsgi_app\n    response = self.full_dispatch_request()\n  File "/home/ai/project/varunClone/venv/lib/python3.9/site-packages/flask/app.py", line 1486, in full_dispatch_request\n    rv = self.handle_user_exception(e)\n  File "/home/ai/project/varunClone/venv/lib/python3.9/site-packages/flask_cors/extension.py", line 176, in wrapped_function\n    return cors_after_request(app.make_response(f(*args, **kwargs)))\n  File "/home/ai/project/varunClone/venv/lib/python3.9/site-packages/flask/app.py", line 1484, in full_dispatch_request\n    rv = self.dispatch_request()\n  File "/home/ai/project/varunClone/venv/lib/python3.9/site-packages/flask/app.py", line 1469, in dispatch_request\n    return self.ensure_sync(self.view_functions[rule.endpoint])(**view_args)\n  File "/home/ai/project/varunClone/SocialAnalytics/Social/src/blueprints/StatesBlueprint.py", line 131, in list_state\n    result_dict_list = [dict(row) for row in result]\n  File "/home/ai/project/varunClone/SocialAnalytics/Social/src/blueprints/StatesBlueprint.py", line 131, in <listcomp>\n    result_dict_list = [dict(row) for row in result]\nTypeError: cannot convert dictionary update sequence element #0 to a sequence
2023-12-14 19:03:30,348 : ERROR : app : log_exception : 1414 : (Process Details : (34095, MainProcess), Thread Details : (139659973658176, Thread-1)) Log : Exception on /api/states/Andhra Pradesh/party/bjp/platform/feed [GET]\nTraceback (most recent call last):\n  File "/home/ai/project/varunClone/venv/lib/python3.9/site-packages/flask/app.py", line 2190, in wsgi_app\n    response = self.full_dispatch_request()\n  File "/home/ai/project/varunClone/venv/lib/python3.9/site-packages/flask/app.py", line 1486, in full_dispatch_request\n    rv = self.handle_user_exception(e)\n  File "/home/ai/project/varunClone/venv/lib/python3.9/site-packages/flask_cors/extension.py", line 176, in wrapped_function\n    return cors_after_request(app.make_response(f(*args, **kwargs)))\n  File "/home/ai/project/varunClone/venv/lib/python3.9/site-packages/flask/app.py", line 1484, in full_dispatch_request\n    rv = self.dispatch_request()\n  File "/home/ai/project/varunClone/venv/lib/python3.9/site-packages/flask/app.py", line 1469, in dispatch_request\n    return self.ensure_sync(self.view_functions[rule.endpoint])(**view_args)\n  File "/home/ai/project/varunClone/SocialAnalytics/Social/src/blueprints/StatesBlueprint.py", line 131, in list_state\n    result_dict_list = [dict(zip(result.keys(), row)) for row in result]\n  File "/home/ai/project/varunClone/SocialAnalytics/Social/src/blueprints/StatesBlueprint.py", line 131, in <listcomp>\n    result_dict_list = [dict(zip(result.keys(), row)) for row in result]\nAttributeError: 'list' object has no attribute 'keys'
2023-12-14 19:04:08,829 : ERROR : app : log_exception : 1414 : (Process Details : (34179, MainProcess), Thread Details : (139760108758592, Thread-1)) Log : Exception on /api/states/Andhra Pradesh/party/bjp/platform/feed [GET]\nTraceback (most recent call last):\n  File "/home/ai/project/varunClone/venv/lib/python3.9/site-packages/flask/app.py", line 2190, in wsgi_app\n    response = self.full_dispatch_request()\n  File "/home/ai/project/varunClone/venv/lib/python3.9/site-packages/flask/app.py", line 1486, in full_dispatch_request\n    rv = self.handle_user_exception(e)\n  File "/home/ai/project/varunClone/venv/lib/python3.9/site-packages/flask_cors/extension.py", line 176, in wrapped_function\n    return cors_after_request(app.make_response(f(*args, **kwargs)))\n  File "/home/ai/project/varunClone/venv/lib/python3.9/site-packages/flask/app.py", line 1484, in full_dispatch_request\n    rv = self.dispatch_request()\n  File "/home/ai/project/varunClone/venv/lib/python3.9/site-packages/flask/app.py", line 1469, in dispatch_request\n    return self.ensure_sync(self.view_functions[rule.endpoint])(**view_args)\n  File "/home/ai/project/varunClone/SocialAnalytics/Social/src/blueprints/StatesBlueprint.py", line 131, in list_state\n    result_dict_list = [dict(zip(result.keys(), row)) for row in result[0]]\n  File "/home/ai/project/varunClone/SocialAnalytics/Social/src/blueprints/StatesBlueprint.py", line 131, in <listcomp>\n    result_dict_list = [dict(zip(result.keys(), row)) for row in result[0]]\nAttributeError: 'list' object has no attribute 'keys'
2023-12-14 19:34:28,269 : ERROR : app : log_exception : 1414 : (Process Details : (36759, MainProcess), Thread Details : (140696271869504, Thread-1)) Log : Exception on /api/states/Andhra Pradesh/party/bjp/platform/feed [GET]\nTraceback (most recent call last):\n  File "/home/ai/project/varunClone/venv/lib/python3.9/site-packages/flask/app.py", line 2190, in wsgi_app\n    response = self.full_dispatch_request()\n  File "/home/ai/project/varunClone/venv/lib/python3.9/site-packages/flask/app.py", line 1486, in full_dispatch_request\n    rv = self.handle_user_exception(e)\n  File "/home/ai/project/varunClone/venv/lib/python3.9/site-packages/flask_cors/extension.py", line 176, in wrapped_function\n    return cors_after_request(app.make_response(f(*args, **kwargs)))\n  File "/home/ai/project/varunClone/venv/lib/python3.9/site-packages/flask/app.py", line 1484, in full_dispatch_request\n    rv = self.dispatch_request()\n  File "/home/ai/project/varunClone/venv/lib/python3.9/site-packages/flask/app.py", line 1469, in dispatch_request\n    return self.ensure_sync(self.view_functions[rule.endpoint])(**view_args)\n  File "/home/ai/project/varunClone/SocialAnalytics/Social/src/blueprints/StatesBlueprint.py", line 130, in list_state\n    dict = dict(('plateform','total-feeds','total-comments','Pro-comments','anit-comments'))\nUnboundLocalError: local variable 'dict' referenced before assignment
2023-12-14 19:44:53,397 : ERROR : app : log_exception : 1414 : (Process Details : (37739, MainProcess), Thread Details : (140251873465920, Thread-1)) Log : Exception on /api/states/Andhra Pradesh/party/bjp/platform/feed [GET]\nTraceback (most recent call last):\n  File "/home/ai/project/varunClone/venv/lib/python3.9/site-packages/flask/app.py", line 2190, in wsgi_app\n    response = self.full_dispatch_request()\n  File "/home/ai/project/varunClone/venv/lib/python3.9/site-packages/flask/app.py", line 1486, in full_dispatch_request\n    rv = self.handle_user_exception(e)\n  File "/home/ai/project/varunClone/venv/lib/python3.9/site-packages/flask_cors/extension.py", line 176, in wrapped_function\n    return cors_after_request(app.make_response(f(*args, **kwargs)))\n  File "/home/ai/project/varunClone/venv/lib/python3.9/site-packages/flask/app.py", line 1484, in full_dispatch_request\n    rv = self.dispatch_request()\n  File "/home/ai/project/varunClone/venv/lib/python3.9/site-packages/flask/app.py", line 1469, in dispatch_request\n    return self.ensure_sync(self.view_functions[rule.endpoint])(**view_args)\n  File "/home/ai/project/varunClone/SocialAnalytics/Social/src/blueprints/StatesBlueprint.py", line 153, in list_state\n    allDict.append(dict)\nAttributeError: 'tuple' object has no attribute 'append'
2023-12-22 09:38:30,023 : ERROR : app : log_exception : 1414 : (Process Details : (620153, MainProcess), Thread Details : (140258527839808, Thread-1)) Log : Exception on /api/states/polytician/42/platform/facebook/feed [GET]\nTraceback (most recent call last):\n  File "/home/ai/project/varunClone/venv/lib/python3.9/site-packages/sqlalchemy/engine/base.py", line 1965, in _exec_single_context\n    self.dialect.do_execute(\n  File "/home/ai/project/varunClone/venv/lib/python3.9/site-packages/sqlalchemy/engine/default.py", line 921, in do_execute\n    cursor.execute(statement, parameters)\nsqlite3.OperationalError: near "'%facebook%'": syntax error\n\nThe above exception was the direct cause of the following exception:\n\nTraceback (most recent call last):\n  File "/home/ai/project/varunClone/venv/lib/python3.9/site-packages/flask/app.py", line 2190, in wsgi_app\n    response = self.full_dispatch_request()\n  File "/home/ai/project/varunClone/venv/lib/python3.9/site-packages/flask/app.py", line 1486, in full_dispatch_request\n    rv = self.handle_user_exception(e)\n  File "/home/ai/project/varunClone/venv/lib/python3.9/site-packages/flask_cors/extension.py", line 176, in wrapped_function\n    return cors_after_request(app.make_response(f(*args, **kwargs)))\n  File "/home/ai/project/varunClone/venv/lib/python3.9/site-packages/flask/app.py", line 1484, in full_dispatch_request\n    rv = self.dispatch_request()\n  File "/home/ai/project/varunClone/venv/lib/python3.9/site-packages/flask/app.py", line 1469, in dispatch_request\n    return self.ensure_sync(self.view_functions[rule.endpoint])(**view_args)\n  File "/home/ai/project/varunClone/SocialAnalytics/Social/src/blueprints/StatesBlueprint.py", line 326, in DemocracyPoliticianPlateform\n    result = db.session.execute(query).fetchall()\n  File "/home/ai/project/varunClone/venv/lib/python3.9/site-packages/sqlalchemy/orm/scoping.py", line 738, in execute\n    return self._proxied.execute(\n  File "/home/ai/project/varunClone/venv/lib/python3.9/site-packages/sqlalchemy/orm/session.py", line 2262, in execute\n    return self._execute_internal(\n  File "/home/ai/project/varunClone/venv/lib/python3.9/site-packages/sqlalchemy/orm/session.py", line 2153, in _execute_internal\n    result = conn.execute(\n  File "/home/ai/project/varunClone/venv/lib/python3.9/site-packages/sqlalchemy/engine/base.py", line 1412, in execute\n    return meth(\n  File "/home/ai/project/varunClone/venv/lib/python3.9/site-packages/sqlalchemy/sql/elements.py", line 516, in _execute_on_connection\n    return connection._execute_clauseelement(\n  File "/home/ai/project/varunClone/venv/lib/python3.9/site-packages/sqlalchemy/engine/base.py", line 1635, in _execute_clauseelement\n    ret = self._execute_context(\n  File "/home/ai/project/varunClone/venv/lib/python3.9/site-packages/sqlalchemy/engine/base.py", line 1844, in _execute_context\n    return self._exec_single_context(\n  File "/home/ai/project/varunClone/venv/lib/python3.9/site-packages/sqlalchemy/engine/base.py", line 1984, in _exec_single_context\n    self._handle_dbapi_exception(\n  File "/home/ai/project/varunClone/venv/lib/python3.9/site-packages/sqlalchemy/engine/base.py", line 2339, in _handle_dbapi_exception\n    raise sqlalchemy_exception.with_traceback(exc_info[2]) from e\n  File "/home/ai/project/varunClone/venv/lib/python3.9/site-packages/sqlalchemy/engine/base.py", line 1965, in _exec_single_context\n    self.dialect.do_execute(\n  File "/home/ai/project/varunClone/venv/lib/python3.9/site-packages/sqlalchemy/engine/default.py", line 921, in do_execute\n    cursor.execute(statement, parameters)\nsqlalchemy.exc.OperationalError: (sqlite3.OperationalError) near "'%facebook%'": syntax error\n[SQL:     \n            SELECT \n            substr(posts.post_content,0,30) as summary,\n            (SELECT count(*) FROM comments WHERE comments.post_id=posts.page_id) as commentsCount,\n            (SELECT sum(CASE WHEN comments.classification=='Pro Government' THEN 1 ELSE 0 END) as proGov  FROM comments WHERE comments.post_id=posts.page_id) as proGov,\n            (SELECT sum(CASE WHEN comments.classification=='Anti Government' THEN 1 ELSE 0 END) as proGov  FROM comments WHERE comments.post_id=posts.page_id) as antiGov, \n            posts.created_on\n\n            FROM posts\n            INNER JOIN pages\n            ON pages.page_id=posts.page_id\n            WHERE Pages.politician_id == 42 and pages.platform_name==like '%facebook%'\n            \n    ]\n(Background on this error at: https://sqlalche.me/e/20/e3q8)
2023-12-22 09:39:04,775 : ERROR : app : log_exception : 1414 : (Process Details : (620153, MainProcess), Thread Details : (140258527839808, Thread-2)) Log : Exception on /api/states/polytician/42/platform/Facebook/feed [GET]\nTraceback (most recent call last):\n  File "/home/ai/project/varunClone/venv/lib/python3.9/site-packages/sqlalchemy/engine/base.py", line 1965, in _exec_single_context\n    self.dialect.do_execute(\n  File "/home/ai/project/varunClone/venv/lib/python3.9/site-packages/sqlalchemy/engine/default.py", line 921, in do_execute\n    cursor.execute(statement, parameters)\nsqlite3.OperationalError: near "'%Facebook%'": syntax error\n\nThe above exception was the direct cause of the following exception:\n\nTraceback (most recent call last):\n  File "/home/ai/project/varunClone/venv/lib/python3.9/site-packages/flask/app.py", line 2190, in wsgi_app\n    response = self.full_dispatch_request()\n  File "/home/ai/project/varunClone/venv/lib/python3.9/site-packages/flask/app.py", line 1486, in full_dispatch_request\n    rv = self.handle_user_exception(e)\n  File "/home/ai/project/varunClone/venv/lib/python3.9/site-packages/flask_cors/extension.py", line 176, in wrapped_function\n    return cors_after_request(app.make_response(f(*args, **kwargs)))\n  File "/home/ai/project/varunClone/venv/lib/python3.9/site-packages/flask/app.py", line 1484, in full_dispatch_request\n    rv = self.dispatch_request()\n  File "/home/ai/project/varunClone/venv/lib/python3.9/site-packages/flask/app.py", line 1469, in dispatch_request\n    return self.ensure_sync(self.view_functions[rule.endpoint])(**view_args)\n  File "/home/ai/project/varunClone/SocialAnalytics/Social/src/blueprints/StatesBlueprint.py", line 326, in DemocracyPoliticianPlateform\n    result = db.session.execute(query).fetchall()\n  File "/home/ai/project/varunClone/venv/lib/python3.9/site-packages/sqlalchemy/orm/scoping.py", line 738, in execute\n    return self._proxied.execute(\n  File "/home/ai/project/varunClone/venv/lib/python3.9/site-packages/sqlalchemy/orm/session.py", line 2262, in execute\n    return self._execute_internal(\n  File "/home/ai/project/varunClone/venv/lib/python3.9/site-packages/sqlalchemy/orm/session.py", line 2153, in _execute_internal\n    result = conn.execute(\n  File "/home/ai/project/varunClone/venv/lib/python3.9/site-packages/sqlalchemy/engine/base.py", line 1412, in execute\n    return meth(\n  File "/home/ai/project/varunClone/venv/lib/python3.9/site-packages/sqlalchemy/sql/elements.py", line 516, in _execute_on_connection\n    return connection._execute_clauseelement(\n  File "/home/ai/project/varunClone/venv/lib/python3.9/site-packages/sqlalchemy/engine/base.py", line 1635, in _execute_clauseelement\n    ret = self._execute_context(\n  File "/home/ai/project/varunClone/venv/lib/python3.9/site-packages/sqlalchemy/engine/base.py", line 1844, in _execute_context\n    return self._exec_single_context(\n  File "/home/ai/project/varunClone/venv/lib/python3.9/site-packages/sqlalchemy/engine/base.py", line 1984, in _exec_single_context\n    self._handle_dbapi_exception(\n  File "/home/ai/project/varunClone/venv/lib/python3.9/site-packages/sqlalchemy/engine/base.py", line 2339, in _handle_dbapi_exception\n    raise sqlalchemy_exception.with_traceback(exc_info[2]) from e\n  File "/home/ai/project/varunClone/venv/lib/python3.9/site-packages/sqlalchemy/engine/base.py", line 1965, in _exec_single_context\n    self.dialect.do_execute(\n  File "/home/ai/project/varunClone/venv/lib/python3.9/site-packages/sqlalchemy/engine/default.py", line 921, in do_execute\n    cursor.execute(statement, parameters)\nsqlalchemy.exc.OperationalError: (sqlite3.OperationalError) near "'%Facebook%'": syntax error\n[SQL:     \n            SELECT \n            substr(posts.post_content,0,30) as summary,\n            (SELECT count(*) FROM comments WHERE comments.post_id=posts.page_id) as commentsCount,\n            (SELECT sum(CASE WHEN comments.classification=='Pro Government' THEN 1 ELSE 0 END) as proGov  FROM comments WHERE comments.post_id=posts.page_id) as proGov,\n            (SELECT sum(CASE WHEN comments.classification=='Anti Government' THEN 1 ELSE 0 END) as proGov  FROM comments WHERE comments.post_id=posts.page_id) as antiGov, \n            posts.created_on\n\n            FROM posts\n            INNER JOIN pages\n            ON pages.page_id=posts.page_id\n            WHERE Pages.politician_id == 42 and pages.platform_name==like '%Facebook%'\n            \n    ]\n(Background on this error at: https://sqlalche.me/e/20/e3q8)
2023-12-22 09:39:54,075 : ERROR : app : log_exception : 1414 : (Process Details : (620312, MainProcess), Thread Details : (139622079919680, Thread-1)) Log : Exception on /api/states/polytician/42/platform/Facebook/feed [GET]\nTraceback (most recent call last):\n  File "/home/ai/project/varunClone/venv/lib/python3.9/site-packages/sqlalchemy/engine/base.py", line 1965, in _exec_single_context\n    self.dialect.do_execute(\n  File "/home/ai/project/varunClone/venv/lib/python3.9/site-packages/sqlalchemy/engine/default.py", line 921, in do_execute\n    cursor.execute(statement, parameters)\nsqlite3.OperationalError: near "'%Facebook%'": syntax error\n\nThe above exception was the direct cause of the following exception:\n\nTraceback (most recent call last):\n  File "/home/ai/project/varunClone/venv/lib/python3.9/site-packages/flask/app.py", line 2190, in wsgi_app\n    response = self.full_dispatch_request()\n  File "/home/ai/project/varunClone/venv/lib/python3.9/site-packages/flask/app.py", line 1486, in full_dispatch_request\n    rv = self.handle_user_exception(e)\n  File "/home/ai/project/varunClone/venv/lib/python3.9/site-packages/flask_cors/extension.py", line 176, in wrapped_function\n    return cors_after_request(app.make_response(f(*args, **kwargs)))\n  File "/home/ai/project/varunClone/venv/lib/python3.9/site-packages/flask/app.py", line 1484, in full_dispatch_request\n    rv = self.dispatch_request()\n  File "/home/ai/project/varunClone/venv/lib/python3.9/site-packages/flask/app.py", line 1469, in dispatch_request\n    return self.ensure_sync(self.view_functions[rule.endpoint])(**view_args)\n  File "/home/ai/project/varunClone/SocialAnalytics/Social/src/blueprints/StatesBlueprint.py", line 326, in DemocracyPoliticianPlateform\n    result = db.session.execute(query).fetchall()\n  File "/home/ai/project/varunClone/venv/lib/python3.9/site-packages/sqlalchemy/orm/scoping.py", line 738, in execute\n    return self._proxied.execute(\n  File "/home/ai/project/varunClone/venv/lib/python3.9/site-packages/sqlalchemy/orm/session.py", line 2262, in execute\n    return self._execute_internal(\n  File "/home/ai/project/varunClone/venv/lib/python3.9/site-packages/sqlalchemy/orm/session.py", line 2153, in _execute_internal\n    result = conn.execute(\n  File "/home/ai/project/varunClone/venv/lib/python3.9/site-packages/sqlalchemy/engine/base.py", line 1412, in execute\n    return meth(\n  File "/home/ai/project/varunClone/venv/lib/python3.9/site-packages/sqlalchemy/sql/elements.py", line 516, in _execute_on_connection\n    return connection._execute_clauseelement(\n  File "/home/ai/project/varunClone/venv/lib/python3.9/site-packages/sqlalchemy/engine/base.py", line 1635, in _execute_clauseelement\n    ret = self._execute_context(\n  File "/home/ai/project/varunClone/venv/lib/python3.9/site-packages/sqlalchemy/engine/base.py", line 1844, in _execute_context\n    return self._exec_single_context(\n  File "/home/ai/project/varunClone/venv/lib/python3.9/site-packages/sqlalchemy/engine/base.py", line 1984, in _exec_single_context\n    self._handle_dbapi_exception(\n  File "/home/ai/project/varunClone/venv/lib/python3.9/site-packages/sqlalchemy/engine/base.py", line 2339, in _handle_dbapi_exception\n    raise sqlalchemy_exception.with_traceback(exc_info[2]) from e\n  File "/home/ai/project/varunClone/venv/lib/python3.9/site-packages/sqlalchemy/engine/base.py", line 1965, in _exec_single_context\n    self.dialect.do_execute(\n  File "/home/ai/project/varunClone/venv/lib/python3.9/site-packages/sqlalchemy/engine/default.py", line 921, in do_execute\n    cursor.execute(statement, parameters)\nsqlalchemy.exc.OperationalError: (sqlite3.OperationalError) near "'%Facebook%'": syntax error\n[SQL:     \n            SELECT \n            substr(posts.post_content,0,30) as summary,\n            (SELECT count(*) FROM comments WHERE comments.post_id=posts.page_id) as commentsCount,\n            (SELECT sum(CASE WHEN comments.classification=='Pro Government' THEN 1 ELSE 0 END) as proGov  FROM comments WHERE comments.post_id=posts.page_id) as proGov,\n            (SELECT sum(CASE WHEN comments.classification=='Anti Government' THEN 1 ELSE 0 END) as proGov  FROM comments WHERE comments.post_id=posts.page_id) as antiGov, \n            posts.created_on\n\n            FROM posts\n            INNER JOIN pages\n            ON pages.page_id=posts.page_id\n            WHERE Pages.politician_id == 42 and pages.platform_name==like '%Facebook%'\n            \n    ]\n(Background on this error at: https://sqlalche.me/e/20/e3q8)
2023-12-22 09:41:39,258 : ERROR : app : log_exception : 1414 : (Process Details : (620529, MainProcess), Thread Details : (140076090918464, Thread-1)) Log : Exception on /api/states/polytician/42/platform/Facebook/feed [GET]\nTraceback (most recent call last):\n  File "/home/ai/project/varunClone/venv/lib/python3.9/site-packages/sqlalchemy/engine/base.py", line 1965, in _exec_single_context\n    self.dialect.do_execute(\n  File "/home/ai/project/varunClone/venv/lib/python3.9/site-packages/sqlalchemy/engine/default.py", line 921, in do_execute\n    cursor.execute(statement, parameters)\nsqlite3.OperationalError: near "'%Facebook%'": syntax error\n\nThe above exception was the direct cause of the following exception:\n\nTraceback (most recent call last):\n  File "/home/ai/project/varunClone/venv/lib/python3.9/site-packages/flask/app.py", line 2190, in wsgi_app\n    response = self.full_dispatch_request()\n  File "/home/ai/project/varunClone/venv/lib/python3.9/site-packages/flask/app.py", line 1486, in full_dispatch_request\n    rv = self.handle_user_exception(e)\n  File "/home/ai/project/varunClone/venv/lib/python3.9/site-packages/flask_cors/extension.py", line 176, in wrapped_function\n    return cors_after_request(app.make_response(f(*args, **kwargs)))\n  File "/home/ai/project/varunClone/venv/lib/python3.9/site-packages/flask/app.py", line 1484, in full_dispatch_request\n    rv = self.dispatch_request()\n  File "/home/ai/project/varunClone/venv/lib/python3.9/site-packages/flask/app.py", line 1469, in dispatch_request\n    return self.ensure_sync(self.view_functions[rule.endpoint])(**view_args)\n  File "/home/ai/project/varunClone/SocialAnalytics/Social/src/blueprints/StatesBlueprint.py", line 326, in DemocracyPoliticianPlateform\n    result = db.session.execute(query).fetchall()\n  File "/home/ai/project/varunClone/venv/lib/python3.9/site-packages/sqlalchemy/orm/scoping.py", line 738, in execute\n    return self._proxied.execute(\n  File "/home/ai/project/varunClone/venv/lib/python3.9/site-packages/sqlalchemy/orm/session.py", line 2262, in execute\n    return self._execute_internal(\n  File "/home/ai/project/varunClone/venv/lib/python3.9/site-packages/sqlalchemy/orm/session.py", line 2153, in _execute_internal\n    result = conn.execute(\n  File "/home/ai/project/varunClone/venv/lib/python3.9/site-packages/sqlalchemy/engine/base.py", line 1412, in execute\n    return meth(\n  File "/home/ai/project/varunClone/venv/lib/python3.9/site-packages/sqlalchemy/sql/elements.py", line 516, in _execute_on_connection\n    return connection._execute_clauseelement(\n  File "/home/ai/project/varunClone/venv/lib/python3.9/site-packages/sqlalchemy/engine/base.py", line 1635, in _execute_clauseelement\n    ret = self._execute_context(\n  File "/home/ai/project/varunClone/venv/lib/python3.9/site-packages/sqlalchemy/engine/base.py", line 1844, in _execute_context\n    return self._exec_single_context(\n  File "/home/ai/project/varunClone/venv/lib/python3.9/site-packages/sqlalchemy/engine/base.py", line 1984, in _exec_single_context\n    self._handle_dbapi_exception(\n  File "/home/ai/project/varunClone/venv/lib/python3.9/site-packages/sqlalchemy/engine/base.py", line 2339, in _handle_dbapi_exception\n    raise sqlalchemy_exception.with_traceback(exc_info[2]) from e\n  File "/home/ai/project/varunClone/venv/lib/python3.9/site-packages/sqlalchemy/engine/base.py", line 1965, in _exec_single_context\n    self.dialect.do_execute(\n  File "/home/ai/project/varunClone/venv/lib/python3.9/site-packages/sqlalchemy/engine/default.py", line 921, in do_execute\n    cursor.execute(statement, parameters)\nsqlalchemy.exc.OperationalError: (sqlite3.OperationalError) near "'%Facebook%'": syntax error\n[SQL:     \n            SELECT \n            substr(posts.post_content,0,30) as summary,\n            (SELECT count(*) FROM comments WHERE comments.post_id=posts.page_id) as commentsCount,\n            (SELECT sum(CASE WHEN comments.classification=='Pro Government' THEN 1 ELSE 0 END) as proGov  FROM comments WHERE comments.post_id=posts.page_id) as proGov,\n            (SELECT sum(CASE WHEN comments.classification=='Anti Government' THEN 1 ELSE 0 END) as proGov  FROM comments WHERE comments.post_id=posts.page_id) as antiGov, \n            posts.created_on\n\n            FROM posts\n            INNER JOIN pages\n            ON pages.page_id=posts.page_id\n            WHERE Pages.politician_id == 42 and pages.platform_name==like '%Facebook%'\n            \n    ]\n(Background on this error at: https://sqlalche.me/e/20/e3q8)
2023-12-22 09:53:08,436 : ERROR : app : log_exception : 1414 : (Process Details : (621702, MainProcess), Thread Details : (140421527467584, Thread-1)) Log : Exception on /api/states/polytician/42/platform/feed [GET]\nTraceback (most recent call last):\n  File "/home/ai/project/varunClone/venv/lib/python3.9/site-packages/flask/app.py", line 2190, in wsgi_app\n    response = self.full_dispatch_request()\n  File "/home/ai/project/varunClone/venv/lib/python3.9/site-packages/flask/app.py", line 1486, in full_dispatch_request\n    rv = self.handle_user_exception(e)\n  File "/home/ai/project/varunClone/venv/lib/python3.9/site-packages/flask_cors/extension.py", line 176, in wrapped_function\n    return cors_after_request(app.make_response(f(*args, **kwargs)))\n  File "/home/ai/project/varunClone/venv/lib/python3.9/site-packages/flask/app.py", line 1484, in full_dispatch_request\n    rv = self.dispatch_request()\n  File "/home/ai/project/varunClone/venv/lib/python3.9/site-packages/flask/app.py", line 1469, in dispatch_request\n    return self.ensure_sync(self.view_functions[rule.endpoint])(**view_args)\nTypeError: DemocracyPolitician() missing 1 required positional argument: 'plateform_id'
2023-12-22 09:53:48,739 : ERROR : app : log_exception : 1414 : (Process Details : (621702, MainProcess), Thread Details : (140421527467584, Thread-2)) Log : Exception on /api/states/polytician/42/platform/feed [GET]\nTraceback (most recent call last):\n  File "/home/ai/project/varunClone/venv/lib/python3.9/site-packages/flask/app.py", line 2190, in wsgi_app\n    response = self.full_dispatch_request()\n  File "/home/ai/project/varunClone/venv/lib/python3.9/site-packages/flask/app.py", line 1486, in full_dispatch_request\n    rv = self.handle_user_exception(e)\n  File "/home/ai/project/varunClone/venv/lib/python3.9/site-packages/flask_cors/extension.py", line 176, in wrapped_function\n    return cors_after_request(app.make_response(f(*args, **kwargs)))\n  File "/home/ai/project/varunClone/venv/lib/python3.9/site-packages/flask/app.py", line 1484, in full_dispatch_request\n    rv = self.dispatch_request()\n  File "/home/ai/project/varunClone/venv/lib/python3.9/site-packages/flask/app.py", line 1469, in dispatch_request\n    return self.ensure_sync(self.view_functions[rule.endpoint])(**view_args)\nTypeError: DemocracyPolitician() missing 1 required positional argument: 'plateform_id'
2023-12-22 09:54:07,103 : ERROR : app : log_exception : 1414 : (Process Details : (621820, MainProcess), Thread Details : (140573969745472, Thread-1)) Log : Exception on /api/states/polytician/42/platform/feed [GET]\nTraceback (most recent call last):\n  File "/home/ai/project/varunClone/venv/lib/python3.9/site-packages/flask/app.py", line 2190, in wsgi_app\n    response = self.full_dispatch_request()\n  File "/home/ai/project/varunClone/venv/lib/python3.9/site-packages/flask/app.py", line 1486, in full_dispatch_request\n    rv = self.handle_user_exception(e)\n  File "/home/ai/project/varunClone/venv/lib/python3.9/site-packages/flask_cors/extension.py", line 176, in wrapped_function\n    return cors_after_request(app.make_response(f(*args, **kwargs)))\n  File "/home/ai/project/varunClone/venv/lib/python3.9/site-packages/flask/app.py", line 1484, in full_dispatch_request\n    rv = self.dispatch_request()\n  File "/home/ai/project/varunClone/venv/lib/python3.9/site-packages/flask/app.py", line 1469, in dispatch_request\n    return self.ensure_sync(self.view_functions[rule.endpoint])(**view_args)\nTypeError: DemocracyPolitician() missing 1 required positional argument: 'plateform_id'
2023-12-22 09:54:35,917 : ERROR : app : log_exception : 1414 : (Process Details : (621820, MainProcess), Thread Details : (140573969745472, Thread-2)) Log : Exception on /api/states/polytician/42/platform/feed [GET]\nTraceback (most recent call last):\n  File "/home/ai/project/varunClone/venv/lib/python3.9/site-packages/flask/app.py", line 2190, in wsgi_app\n    response = self.full_dispatch_request()\n  File "/home/ai/project/varunClone/venv/lib/python3.9/site-packages/flask/app.py", line 1486, in full_dispatch_request\n    rv = self.handle_user_exception(e)\n  File "/home/ai/project/varunClone/venv/lib/python3.9/site-packages/flask_cors/extension.py", line 176, in wrapped_function\n    return cors_after_request(app.make_response(f(*args, **kwargs)))\n  File "/home/ai/project/varunClone/venv/lib/python3.9/site-packages/flask/app.py", line 1484, in full_dispatch_request\n    rv = self.dispatch_request()\n  File "/home/ai/project/varunClone/venv/lib/python3.9/site-packages/flask/app.py", line 1469, in dispatch_request\n    return self.ensure_sync(self.view_functions[rule.endpoint])(**view_args)\nTypeError: DemocracyPolitician() missing 1 required positional argument: 'plateform_id'
2023-12-22 16:34:41,067 : ERROR : app : log_exception : 1414 : (Process Details : (661288, MainProcess), Thread Details : (140473520772672, Thread-1)) Log : Exception on /api/states/polytician/42/dashboard/feed [GET]\nTraceback (most recent call last):\n  File "/home/ai/project/varunClone/venv/lib/python3.9/site-packages/flask/app.py", line 2190, in wsgi_app\n    response = self.full_dispatch_request()\n  File "/home/ai/project/varunClone/venv/lib/python3.9/site-packages/flask/app.py", line 1486, in full_dispatch_request\n    rv = self.handle_user_exception(e)\n  File "/home/ai/project/varunClone/venv/lib/python3.9/site-packages/flask_cors/extension.py", line 176, in wrapped_function\n    return cors_after_request(app.make_response(f(*args, **kwargs)))\n  File "/home/ai/project/varunClone/venv/lib/python3.9/site-packages/flask/app.py", line 1484, in full_dispatch_request\n    rv = self.dispatch_request()\n  File "/home/ai/project/varunClone/venv/lib/python3.9/site-packages/flask/app.py", line 1469, in dispatch_request\n    return self.ensure_sync(self.view_functions[rule.endpoint])(**view_args)\n  File "/home/ai/project/varunClone/SocialAnalytics/Social/src/blueprints/StatesBlueprint.py", line 452, in DemocracyPoliticianPlateformSummary\n    facebook['total-feeds']=int(facebook['total-feeds'])+1\nTypeError: tuple indices must be integers or slices, not str
2023-12-22 16:35:44,469 : ERROR : app : log_exception : 1414 : (Process Details : (661402, MainProcess), Thread Details : (140656948782656, Thread-1)) Log : Exception on /api/states/polytician/42/dashboard/feed [GET]\nTraceback (most recent call last):\n  File "/home/ai/project/varunClone/venv/lib/python3.9/site-packages/flask/app.py", line 2190, in wsgi_app\n    response = self.full_dispatch_request()\n  File "/home/ai/project/varunClone/venv/lib/python3.9/site-packages/flask/app.py", line 1486, in full_dispatch_request\n    rv = self.handle_user_exception(e)\n  File "/home/ai/project/varunClone/venv/lib/python3.9/site-packages/flask_cors/extension.py", line 176, in wrapped_function\n    return cors_after_request(app.make_response(f(*args, **kwargs)))\n  File "/home/ai/project/varunClone/venv/lib/python3.9/site-packages/flask/app.py", line 1484, in full_dispatch_request\n    rv = self.dispatch_request()\n  File "/home/ai/project/varunClone/venv/lib/python3.9/site-packages/flask/app.py", line 1469, in dispatch_request\n    return self.ensure_sync(self.view_functions[rule.endpoint])(**view_args)\n  File "/home/ai/project/varunClone/SocialAnalytics/Social/src/blueprints/StatesBlueprint.py", line 452, in DemocracyPoliticianPlateformSummary\n    facebook['total-feeds']=int(facebook['total-feeds'])+int(1)\nTypeError: tuple indices must be integers or slices, not str
2023-12-22 16:36:52,637 : ERROR : app : log_exception : 1414 : (Process Details : (661522, MainProcess), Thread Details : (139706760857152, Thread-1)) Log : Exception on /api/states/polytician/42/dashboard/feed [GET]\nTraceback (most recent call last):\n  File "/home/ai/project/varunClone/venv/lib/python3.9/site-packages/flask/app.py", line 2190, in wsgi_app\n    response = self.full_dispatch_request()\n  File "/home/ai/project/varunClone/venv/lib/python3.9/site-packages/flask/app.py", line 1486, in full_dispatch_request\n    rv = self.handle_user_exception(e)\n  File "/home/ai/project/varunClone/venv/lib/python3.9/site-packages/flask_cors/extension.py", line 176, in wrapped_function\n    return cors_after_request(app.make_response(f(*args, **kwargs)))\n  File "/home/ai/project/varunClone/venv/lib/python3.9/site-packages/flask/app.py", line 1484, in full_dispatch_request\n    rv = self.dispatch_request()\n  File "/home/ai/project/varunClone/venv/lib/python3.9/site-packages/flask/app.py", line 1469, in dispatch_request\n    return self.ensure_sync(self.view_functions[rule.endpoint])(**view_args)\n  File "/home/ai/project/varunClone/SocialAnalytics/Social/src/blueprints/StatesBlueprint.py", line 453, in DemocracyPoliticianPlateformSummary\n    facebook['total-feeds']=int(facebook['total-feeds'])+1\nTypeError: tuple indices must be integers or slices, not str
2023-12-27 17:26:38,835 : ERROR : app : log_exception : 1414 : (Process Details : (1082319, MainProcess), Thread Details : (139803249497664, Thread-5)) Log : Exception on /api/facebook/livefeed [GET]\nTraceback (most recent call last):\n  File "/home/ai/project/varunClone/venv/lib/python3.9/site-packages/flask/app.py", line 2190, in wsgi_app\n    response = self.full_dispatch_request()\n  File "/home/ai/project/varunClone/venv/lib/python3.9/site-packages/flask/app.py", line 1487, in full_dispatch_request\n    return self.finalize_request(rv)\n  File "/home/ai/project/varunClone/venv/lib/python3.9/site-packages/flask/app.py", line 1506, in finalize_request\n    response = self.make_response(rv)\n  File "/home/ai/project/varunClone/venv/lib/python3.9/site-packages/flask/app.py", line 1801, in make_response\n    raise TypeError(\nTypeError: The view function for 'facebook_app.livefeed' did not return a valid response. The function either returned None or ended without a return statement.
